Workbook

Sheet THÁNG 12
A2: BẢNG CÔNG NỢ THÁNG 10
A3: CHI NHÁNH | C3: SỐ TIỀN | D3: ĐÃ CK/NGÀY | E3: CÔNG NỢ THÁNG
A4: BẾN TRE | B4: TUẦN 1/12 | C4: 3190000 | D4: R | E4: =SUM(C7) -> 15007500
B5: TUẦN 2/12 | C5: 29930000 | D5: R
B6: TUẦN 3/12 | C6: 7971000 | D6: R
B7: TUẦN 4/12 | C7: 15007500
A9: CÁI BÈ | B9: Tháng 11 | C9: =sum('THÁNG 11'!C9:C12) -> #REF! | D9: R | E9: =sum(C11:C13) -> 51366800
B10: Tuần 1/12 | C10: 9086800 | D10: R
B11: Tuần 2/12 | C11: 12206800
B12: Tuần 3/12 | C12: 11005000
B13: TUẦN 4/12 | C13: 28155000
A14: CAI LẬY | B14: Tuần 1/12 | C14: 9350000 | D14: R | E14: =sum(C15:C16) -> 15200000
B15: Tuần 3/12 | C15: 7600000
B16: TUẦN 4/12 | C16: 7600000
A18: TÂN AN | E18: =sum(C20:C22) -> 47440000
B20: Tuần 3/12 | C20: 25135000
B21: TUẦN 4/12 | C21: 22305000
A23: THỦ ĐỨC | B23: Tuần 1/12 | C23: 27240000 | E23: =sum(C23:C26) -> 50510000
B24: Tuần 3/12 | C24: 23270000 | J24: =H27
B25: TUẦN 4/12 | C25: 0
A27: THANH BÌNH | B27: TUẦN 1/12 | C27: 46099500 | D27: R | E27: =SUM(C29:C30) -> 60119000
B28: TUẦN 2/12 | C28: 45834000 | D28: R
B29: TUẦN 3/12 | C29: 31221500
B30: TUẦN 4/12 | C30: 28897500
B31: CÒN N31/12
A32: TÂN BÌNH | B32: Tháng 11 | C32: =SUM('THÁNG 11'!C36:C37) -> #REF! | D32: R | E32: =SUM(C34:C35) -> 20911000
B33: TUẦN 1/12 | C33: 26880000 | D33: R
B34: TUẦN 3/12 | C34: 10710500
B35: TUẦN 4/12 | C35: 10200500
A37: AN LONG | B37: Tháng 11 | C37: =sum('THÁNG 11'!C39:C40) -> #REF! | D37: R | E37: =SUM(C41) -> 40046000
B38: Tuần 1/12 | C38: 21007500 | D38: R
B39: Tuần 2/12 | C39: 22023400 | D39: R
B40: Tuần 3/12 | C40: 23120600 | D40: R
B41: TUẦN 4/12 | C41: 40046000
A42: BÚN ĐẬU | B42: Tháng 11 | C42: =sum('THÁNG 11'!C44:C48) -> #REF! | D42: R | E42: =sum(C43:C46) -> 32049000
B43: Tuần 1/12 | C43: 6661000
B44: Tuần 2/12 | C44: 6088000
B45: Tuần 3/12 | C45: 5878000
B46: TUẦN 4/12 | C46: 13422000
A49: HỒNG NGỰ | B49: Tuần 1/12 | C49: 87013400 | D49: R | E49: =SUM(C52) -> 98564100
...

Sheet THÁNG 1
A2: BẢNG CÔNG NỢ THÁNG 1
A3: CHI NHÁNH | C3: SỐ TIỀN | D3: ĐÃ CK/NGÀY | E3: CÔNG NỢ THÁNG
A4: BẾN TRE | B4: THÁNG 1 Tuần 1 | C4: 3660000 | D4: R | E4: 0
B5: TUẦN 2 | C5: 7099500 | D5: R
B6: TUẦN 4 | C6: 3115000 | D6: R
B10: Khô- Tết | C10: 14020000 | D10: R
A11: CÁI BÈ | B11: Tuần 2/12 | C11: 12206800 | E11: =sum(C11:C18) -> 130522200
B12: Tuần 3/12 | C12: 11005000
B13: TUẦN 4/12 | C13: 28155000
B14: THÁNG 1 Tuần 1 | C14: 0
B15: TUẦN 2 | C15: 6713600
B16: Tuần 3 | C16: 12846800
B17: TUẦN 4 | C17: 7975000
B18: Khô- Tết | C18: 51620000
A19: CAI LẬY | B19: Tuần 3/12 | C19: 7600000 | D19: R | E19: =sum(C20:C25) -> 30400000
B20: TUẦN 4/12 | C20: 7600000
B21: THÁNG 1 | C21: 0
B22: TUẦN 2 | C22: 0 | G22: =4500*20 -> 90000
B23: Tuần 3 | C23: 7600000
B24: TUẦN 4 | C24: 0
B25: Khô- Tết | C25: 15200000
A26: TÂN AN | B26: Tuần 3/12 | C26: 25135000 | D26: R | E26: 0 | H26: =4500*20 -> 90000
B27: TUẦN 4/12 | C27: 22305000 | D27: R
B28: THÁNG 1 | C28: 52595000 | D28: R
B29: TUẦN 4
B32: Khô- Tết | C32: 29820000 | D32: r
A33: THỦ ĐỨC | B33: THÁNG 1 | C33: 23740000 | D33: R | E33: 0
B34: Tuần 3 | C34: 19340000 | D34: R | J34: =H37
B35: TUẦN 4 | C35: 0
A37: THANH BÌNH | B37: Tuần 2 | C37: 71250000 | D37: R | E37: =SUM(C39:C42) -> 228109000
B38: Tuần 3 | C38: 52369000 | D38: R
B39: Tuần 4 | C39: 53864000
B42: Khô- Tết | C42: 174245000
A43: TÂN BÌNH | B43: TUẦN 4/12 | C43: 10200500 | D43: R | E43: 0
B44: THÁNG 1 | C44: 29532000 | D44: R
B46: Tuần 3 | C46: 7933000 | D46: R
B47: Tuần 4 | C47: 5470000 | D47: R
B49: Khô- Tết | C49: 24572000 | D49: R
A50: AN LONG | E50: =C56 -> 5554000
B52: Tuần 2 | C52: 29274100 | D52: R
...

Sheet THÁNG 2
A2: BẢNG CÔNG NỢ THÁNG 2
A3: CHI NHÁNH | C3: SỐ TIỀN | D3: ĐÃ CK/NGÀY | E3: CÔNG NỢ THÁNG
A4: BẾN TRE | B4: Tuần 3/2 | C4: 4567500 | E4: =SUM(C4:C5) -> 45547500
B5: Tuần 4/2 | C5: 40980000
A11: CÁI BÈ | B11: Khô- Tết | C11: 51620000 | E11: =sum(C11:C18) -> 66430000
B12: Tuần 2/2 | C12: 2130000
B13: Tuần 3/2 | C13: 7670000
B14: Tuần 4/2 | C14: 5010000
A21: CAI LẬY | B21: Tuần 3/12 | C21: 7600000 | D21: R | E21: =sum(C24:C26) -> 21600000
B22: TUẦN 4/12 | C22: 7600000 | D22: R
B23: Tuần 3 | C23: 7600000 | D23: R
B24: Khô- Tết | C24: 10200000 | G24: =4500*20 -> 90000
B25: Tuần 2/2 | C25: 3800000
B26: Tuần 3/2 | C26: 7600000
B27: Tuần 4/2 | C27: 0
A29: TÂN AN | B29: Tuần 3/2 | C29: 44135000 | E29: =SUM(C29:C30) -> 47435000 | H29: =4500*20 -> 90000
B30: Tuần 4/2 | C30: 3300000
A36: THỦ ĐỨC | B36: Tuần 2/2 | C36: 25915000 | E36: =SUM(C36:C38) -> 44215000
B37: Tuần 3/2 | C37: 0 | J37: =H40
B38: Tuần 4/2 | C38: 18300000
A40: THANH BÌNH | B40: Tuần 3/2 | C40: 23770500 | E40: =SUM(C40:C41) -> 49460000
B41: Tuần 4/2 | C41: 25689500
A48: TÂN BÌNH | B48: Tuần 1/2 | C48: 16087500 | E48: =SUM(C48:C50) -> 39093000
B49: Tuần 3/2 | C49: 19705500
B50: Tuần 4/2 | C50: 3300000
A55: AN LONG | B55: Khô- Tết | C55: 17490000 | D55: R | E55: =SUM(C56:C62) -> 73140400
B56: Tuần 1/2 | C56: 41254800
B57: Tuần 2/2 | C57: 2250000
B58: Tuần 3/2 | C58: 0
B59: Tuần 4/2 | C59: 29635600
A63: BÚN ĐẬU | B63: THÁNG 1 | C63: 1212000 | E63: =sum(C63:C70) -> 105515000
B64: Tuần 2 | C64: 5466000
B65: Tuần 3 | C65: 10372000
B66: Khô- Tết | C66: 62990000
B67: Tuần 1/2 | C67: 7224000
B68: Tuần 2/2 | C68: 8000000
B69: Tuần 3/2 | C69: 1864000
B70: Tuần 4/2 | C70: 8387000
A74: HỒNG NGỰ | B74: Tuần 1/2 | C74: 29145000 | D74: R | E74: =SUM(C77) -> 82053500
B75: Tuần 2/2 | C75: 19553300 | D75: R
...

Sheet THÁNG 3
A2: BẢNG CÔNG NỢ THÁNG 3
A3: CHI NHÁNH | C3: SỐ TIỀN | D3: ĐÃ CK/NGÀY | E3: CÔNG NỢ THÁNG
A4: BẾN TRE | B4: Tuần 3/2 | C4: 4567500 | D4: R | E4: =SUM(C9) -> 43360500
B5: Tuần 4/2 | C5: 40980000 | D5: R
B6: Tuần 1/3 | C6: 4460500 | D6: R
B7: Tuần 2/3 | C7: 8201000 | D7: R
B8: Tuần 3/3 | C8: 4484000 | D8: R
B9: Tuần 4/3 | C9: 43360500
A11: CÁI BÈ | B11: Khô- Tết | C11: 51620000 | D11: R | E11: =sum(C12:C18) -> 54182200
B12: Tuần 2/2 | C12: 2130000
B13: Tuần 3/2 | C13: 7670000
B14: Tuần 4/2 | C14: 5010000
B15: Tuần 1/3 | C15: 8833600
B16: Tuần 2/3 | C16: 11668600
B17: Tuần 3/3 | C17: 7655000
B18: Tuần 4/3 | C18: 11215000
A21: CAI LẬY | B21: Khô- Tết | C21: 15200000 | D21: R | E21: =sum(C22:C26) -> 26600000
B22: Tuần 2/2 | C22: 3800000
B23: Tuần 3/2 | C23: 7600000
B24: Tuần 1/3 | C24: 7600000 | G24: =4500*20 -> 90000
B25: Tuần 2/3 | C25: 0
B26: Tuần 3/3 | C26: 7600000
B27: Tuần 4/3
A29: TÂN AN | B29: Tuần 3/2 | C29: 44135000 | D29: R | E29: =SUM(C33) -> 63120000 | H29: =4500*20 -> 90000
B30: Tuần 4/2 | C30: 3300000 | D30: R
B31: Tuần 1/3 | C31: 35280000 | D31: R
B32: Tuần 2/3 | C32: 42285000 | D32: R
B33: Tuần 4/3 | C33: 63120000
A36: THỦ ĐỨC | B36: Tuần 1/3 | C36: 23740000 | E36: =SUM(C36:C37) -> 48995000
B37: Tuần 2/3 | C37: 25255000 | J37: =H40
A40: THANH BÌNH | B40: Tuần 3/2 | C40: 23770500 | D40: R | E40: =SUM(C44:C45) -> 74844500
B41: Tuần 4/2 | C41: 25689500 | D41: R
B42: Tuần 1/3 | C42: 53064500 | D42: R
B43: Tuần 2/3 | C43: 41820500 | D43: R
B44: Tuần 3/3 | C44: 31334500
B45: Tuần 4/3 | C45: 43510000
B46: CÒN NGÀY 31
A48: TÂN BÌNH | B48: Tuần 2/3 | C48: 3555000 | D48: R | E48: =SUM(C50) -> 5730000
B49: Tuần 3/3 | C49: 1472500 | D49: R
B50: Tuần 4/3 | C50: 5730000
...

Sheet THÁNG 4
A2: BẢNG CÔNG NỢ THÁNG 4
A3: CHI NHÁNH | C3: SỐ TIỀN | D3: ĐÃ CK/NGÀY | E3: CÔNG NỢ THÁNG
A4: BẾN TRE | B4: tuần 2/4 | C4: 4480000 | D4: R | E4: 0
B5: tuần 3/4 | C5: 3945500 | D5: R
B6: tuần 4/4 | C6: 48419000 | D6: R
A11: CÁI BÈ | E11: =sum(C18:C21) -> 62958200
B18: tuần 1/4 | C18: 13370000
B19: tuần 2/4 | C19: 8760000
B20: tuần 3/4 | C20: 12288200
B21: tuần 4/4 | C21: 28540000
A22: CAI LẬY | B22: Tuần 2/2 | C22: 3800000 | E22: =sum(C22:C28) -> 53525000
B23: Tuần 3/2 | C23: 7600000
B24: Tuần 1/3 | C24: 7600000
B25: Tuần 3/3 | C25: 7600000 | G25: =4500*20 -> 90000
B26: Tuần 1/4 | C26: 10075000
B27: tuần 3/4 | C27: 9250000
B28: tuần 4/4 | C28: 7600000
A30: TÂN AN | B30: Tuần 1/4 | C30: 56705000 | D30: R | E30: 0 | H30: =4500*20 -> 90000
B31: tuần 2/4 | C31: 17150000 | D31: R
B32: tuần 3/4 | C32: 31807500 | D32: R
B33: tuần 4/4 | C33: 85975000 | D33: R
A37: THỦ ĐỨC
J38: =H41
A41: THANH BÌNH | E41: 0
A49: TÂN BÌNH | E49: =SUM(C51:C52) -> 8148500
B51: Tuần 2/4 | C51: 2977000
B52: tuần 3/4 | C52: 5171500
A56: AN LONG | E56: =SUM(C62) -> 60794500
B62: tuần 4/4 | C62: 60794500
A64: BÚN ĐẬU | E64: =SUM(C64:C69) -> 0
A75: HỒNG NGỰ | E75: =SUM(C79) -> 0
A83: TÂN HỒNG | E83: =sum(C84:C89) -> 0
A92: TAM NÔNG | E92: 0
A99: LONG MỸ
A109: NGÃ 5 - SÓC TRĂNG | E109: =sum(C111:C122) -> 0
A123: SA ĐÉC | E123: 0
A132: CÁI TÀU HẠ | E132: =SUM(C137) -> 0
A139: HÒA PHÚ-VĨNH LONG | E139: 0
A145: THỐT NỐT | E145: =sum(C147:C152) -> 0
A156: LAI VUNG | E156: =SUM(C158:C166) -> 0
...

Sheet THÁNG 5
A2: BẢNG CÔNG NỢ THÁNG 4
A3: CHI NHÁNH | C3: SỐ TIỀN | D3: ĐÃ CK/NGÀY | E3: CÔNG NỢ THÁNG
A4: BẾN TRE | B4: tuần 1/5 | C4: 7431500 | D4: R | E4: =sum(C7) -> 5385000
B5: tuần 2/5 | C5: 43181000 | D5: R
B6: tuần 3/5 | C6: 4191000 | D6: R
B7: tuần 4/5 | C7: 5385000
A11: CÁI BÈ | B11: tuần 1/4 | C11: 13370000 | D11: R | E11: =sum(C15:C18) -> 44365000
B12: tuần 2/4 | C12: 8760000 | D12: R
B13: tuần 3/4 | C13: 12288200 | D13: R
B14: tuần 4/4 | C14: 28540000 | D14: R
B15: tuần 1/5 | C15: 10426800
B16: tuần 2/5 | C16: 8780000
B17: tuần 3/5 | C17: 8623200
B18: tuần 4/5 | C18: 16535000
A19: CAI LẬY | B19: tháng 2 | C19: 11400000 | D19: R | E19: =sum(C20:C23) -> 58975000
B20: tháng 3 | C20: 15200000
B21: tháng 4 | C21: 26925000
B22: tuần 1/5 | C22: 9250000 | G22: =4500*20 -> 90000
B23: tuần 4/5 | C23: 7600000
A27: TÂN AN | B27: tuần 1/5 | C27: 33740000 | D27: R | E27: 16790000 | H27: =4500*20 -> 90000
B28: tuần 2/5 | C28: 53390000 | D28: R
B29: tuần 3/5 | C29: 16790000
A31: THỦ ĐỨC | B31: tuần 1/5 | C31: 22620000 | D31: R | E31: 27840000
B32: tuần 2/5 | C32: 28060000 | D32: R | J32: =H35
B33: tuần 4/5 | C33: 27840000
A35: THANH BÌNH | B35: tuần 1/5 | C35: 59124000 | D35: R | E35: =sum(C37:C38) -> 59243000
B36: tuần 2/5 | C36: 44704500 | D36: R
B37: tuần 3/5 | C37: 25568500
B38: tuần 4/5 | C38: 33674500
A39: TÂN BÌNH | B39: tháng 4 | C39: 8148000 | D39: R | E39: =sum(C43:C44) -> 7018000
B40: tuần 1/5 | C40: 5799000 | D40: R
B41: tuần 4/4 | C41: 25970000 | D41: R
B42: tuần 2/5 | C42: 4677000 | D42: R
B43: tuần 3/5 | C43: 4302000
B44: tuần 4/5 | C44: 2716000
A45: AN LONG | B45: tuần 4/4 | C45: 35794000 | D45: R | E45: =sum(C48:C49) -> 36198800
B46: tuần 1/5 | C46: 22775800 | D46: R
B47: tuần 2/5 | C47: 20721400 | D47: R
B48: tuần 3/5 | C48: 18301100
B49: tuần 4/5 | C49: 17897700
...

Sheet THÁNG 7
A2: BẢNG CÔNG NỢ THÁNG 7
A3: CHI NHÁNH | C3: SỐ TIỀN | D3: CÔNG NỢ THÁNG
A4: CHỢ LÁCH | B4: tuần 3/7 | C4: 3955500 | D4: =sum(C4:C6) -> 15610500
B5: tuần 4/7 | C5: 4860000
B6: tuần 5/7 | C6: 6795000
A10: cái bè | B10: tháng 6 | C10: 44661000 | D10: =sum(C10:C15) -> 98240600
B11: tuần 1/7 | C11: 11523200
B12: tuần 2/7 | C12: 10295000
B13: tuần 3/7 | C13: 9416400
B14: tuần 4/7 | C14: 11525000
B15: tuần 5/7 | C15: 10820000
A16: cái lậy | B16: tháng 4 | C16: 16850000 | D16: =sum(C16:C20) -> 64100000
B17: tháng 5 | C17: 16850000
B18: tháng 6 | C18: 15200000
B19: tuần 2/7 | C19: 7600000
B20: tuần 4/7 | C20: 7600000
A22: TÂN AN | D22: 690000
B24: tuần 5/7 | C24: 690000
A26: THỦ ĐỨC | D26: 0
I27: =#REF! -> #REF!
A30: THANH BÌNH | D30: =sum(C31:C32) -> 62576000
B31: tuần 4/7 | C31: 29322500
B32: tuần 5/7 | C32: 33253500
A34: TÂN BÌNH | B34: tuần 2/7 | C34: 3905000 | D34: =sum(C34:C36) -> 14084500
B35: tuần 4/7 | C35: 6412000
B36: tuần 5/7 | C36: 3767500
A40: AN LONG | D40: =sum(C42:C43) -> 41563400
B42: tuần 4/7 | C42: 29805600
B43: tuần 5/7 | C43: 11757800
A45: HỒNG NGỰ | B45: tuần 4/6 | C45: thanh toán rồi | D45: 79664300
B46: tuần 4/7 | C46: 79664300 | D46: =sum(C46:C47) -> 145978100
B47: tuần 5/7 | C47: 66313800
B48: còn đơn 31/7
A50: tân hồng | B50: tháng 6 | C50: 81333500 | D50: =sum(C50:C54) -> 221691900
B51: tuần 2/7 | C51: 34673400
B52: tuần 3/7 | C52: 38797000
B53: tuần 4/7 | C53: 35385900
B54: tuần 5/7 | C54: 31502100
A55: TAM NÔNG | B55: tuần 4/7 | C55: 30455600 | D55: =sum(C55:C56) -> 61632600
B56: tuần 5/7 | C56: 31177000
...

Sheet THÁNG 8
A2: BẢNG CÔNG NỢ THÁNG 8
A3: CHI NHÁNH | C3: SỐ TIỀN | D3: CÔNG NỢ THÁNG
A4: CHỢ LÁCH | B4: tuấn 4/8 | C4: 57100500 | D4: =sum(C4:C5) -> 57100500
A10: cái bè | D10: =sum(C11:C15) -> 104698600
B11: tháng 7 | C11: 53579600
B12: tuần 1/8 | C12: 11595000
B13: tuần 2/8 | C13: 10643000
B14: tuần 3/8 | C14: 11506000
B15: tuấn 4/8 | C15: 17375000
A16: cái lậy | D16: =sum(C17:C22) -> 66250000
B17: tháng 5 | C17: 16850000
B18: tháng 6 | C18: 15200000
B19: tháng 7 | C19: 15200000
B20: tuần 1/8 | C20: 7600000
B21: tuần 3/8 | C21: 3800000
B22: tuấn 4/8 | C22: 7600000
A23: TÂN AN | D23: =sum(C23:C24) -> 59735500
B24: tuấn 4/8 | C24: 59735500
A27: THỦ ĐỨC | B27: tuần 1/8 | C27: 23740000 | D27: =sum(C27:C28) -> 53240000
B28: tuần 2/8 | C28: 29500000 | I28: =#REF! -> #REF!
A31: THANH BÌNH | B31: tuần 3/8 | C31: 47583000 | D31: =sum(C31:C32) -> 79465000
B32: tuấn 4/8 | C32: 31882000
A36: TÂN BÌNH | B36: tuần 1/8 | C36: 17863500 | D36: =sum(C36:C37) -> 26013500
B37: tuấn 4/8 | C37: 8150000
A42: AN LONG | B42: tuần 3/8 | C42: 30827600 | D42: =sum(C42:C43) -> 58902600
B43: tuấn 4/8 | C43: 28075000
A47: HỒNG NGỰ | B47: tuần 4/6 | C47: thanh toán rồi | D47: 79664300
B48: tuấn 4/8 | C48: 88444100 | D48: =sum(C48:C49) -> 88444100
A52: tân hồng | D52: =sum(C53:C57) -> 249082000
B53: tháng 7 | C53: 91690000
B54: tuần 1/8 | C54: 34423100
B55: tuần 2/8 | C55: 40003400
B56: tuần 3/8 | C56: 49201200
B57: tuấn 4/8 | C57: 33764300
A58: TAM NÔNG | D58: 50021800
B59: tuấn 4/8 | C59: 50021800
A64: long mỹ | D64: =sum(C65:C69) -> 146413000
B65: tháng 6 | C65: 45658000
B66: tháng 7 | C66: 37208000
B67: tuần 1/8 | C67: 34678000
...

Sheet THÁNG 9
A1: 0
A2: BẢNG CÔNG NỢ THÁNG 9
A3: CHI NHÁNH | C3: SỐ TIỀN | D3: CÔNG NỢ THÁNG
A4: CHỢ LÁCH | B4: tuần 2/9 | C4: 3557500 | D4: =sum(C4:C6) -> 46902500
B5: tuần 3/9 | C5: 6412500
B6: tuần 4/9 | C6: 36932500
A10: cái bè | D10: =sum(C12:C16) -> 89959000
B12: tháng 8 | C12: 51119000
B13: tuần 1/9 | C13: 10495000
B14: tuần 2/9 | C14: 9095000
B15: tuần 3/9 | C15: 7260000
B16: tuần 4/9 | C16: 11990000
A17: cái lậy | D17: =sum(C18:C23) -> 81450000
B18: tháng 5 | C18: 16850000
B19: tháng 6 | C19: 15200000
B20: tháng 7 | C20: 15200000
B21: tháng 8 | C21: 19000000
B22: tuần 2/9 | C22: 7600000
B23: tuần 4/9 | C23: 7600000
A24: TÂN AN | B24: tuần 3/9 | C24: 52110000 | D24: =sum(C24:C25) -> 125610000
B25: tuần 4/9 | C25: 73500000
A28: THỦ ĐỨC | D28: =sum(C28:C29) -> 13000000
B29: tuần 3/9 | C29: 13000000 | I29: =#REF! -> #REF!
A32: THANH BÌNH | B32: tuần 4/9 | C32: 70469000 | D32: 70469000
A37: TÂN BÌNH | D37: =sum(C39:C41) -> 49090500
B39: tuần 2/9 | C39: 10215000
B40: tuần 3/9 | C40: 6388500
B41: tuần 1/10 | C41: 32487000
A43: AN LONG | B43: tuần 4/9 | C43: 25902000 | D43: =sum(C43:C44) -> 54672400
B44: tuần 1/10 | C44: 28770400
A48: HỒNG NGỰ | B48: tuần 4/6 | C48: thanh toán rồi | D48: 79664300
D49: 141192700
B51: tuần 4/9 | C51: 141192700
A53: tân hồng | D53: =sum(C55:C59) -> 271025500
B55: tháng 8 | C55: 82391000
B56: tuần 1/9 | C56: 47749100
B57: tuần 2/9 | C57: 38920900
B58: tuần 3/9 | C58: 32104200
B59: tuần 4/9 | C59: 69860300
A60: TAM NÔNG | D60: 54087500
...

Sheet THANG 10
A2: BẢNG CÔNG NỢ THÁNG 10
A3: CHI NHÁNH | C3: SỐ TIỀN | D3: CÔNG NỢ THÁNG
A4: CHỢ LÁCH | B4: tuần 1/10 | C4: TTR | D4: =sum(C6:C8) -> 51266000
B5: tuần 2/10 | C5: TTR
B6: Tuần 3/10 | C6: 2900000 | E6: 0352909819 lương quang
B7: tuần 4/10 | C7: 43655000
B8: tuần 5/10 | C8: 4711000
E9: NHI
A10: cái bè | B10: tháng 9 | C10: 38840000 | D10: =sum(C10:C14) -> 77930000
B11: tuần 2/10 | C11: 8635000
B12: Tuần 3/10 | C12: 13075000 | E12: 0989969719 minh thiện
B13: tuần 4/10 | C13: 14245000
B14: tuần 5/10 | C14: 3135000 | E14: NHI
A15: Cai lậy | B15: tháng 7 | C15: 15200000 | D15: =sum(C15:C20) -> 64600000
B16: tháng 8 | C16: 19000000
B17: tháng 9 | C17: 15200000 | E17: 0868762644 thiện
B18: tuần 2/10 | C18: 7600000
B19: tuần 4/10 | C19: 7600000
B20: tuần 5/10 | C20: 0 | E20: NHI
A21: TÂN AN | B21: tuần 4/10 | C21: 39070000 | D21: =sum(C21:C23) -> 276474000
B22: tuần 5/10 | C22: 237404000 | E22: 0937743386 hà nhung
E24: NHI
A25: THANH BÌNH | B25: tuần 4/9 | C25: 44469000 | D25: =sum(C25:C27) -> 162855000
B26: tuần 2/10 | C26: 30696000
B27: TUẦN 3/10 | C27: 87690000 | E27: X
E28: còn đơn khai trương
E29: NHI
A30: TÂN BÌNH | B30: tuần 5/10 | C30: 4083000 | D30: =sum(C30:C33) -> 4083000
E32: X
E34: 0368930139 tiểu tư
A35: AN LONG | B35: tuần 2/10 | C35: =31984100-21229600 -> 10754500 | D35: =sum(C35:C38) -> 87586800
B36: Tuần 3/10 | C36: =26212900-30000 -> 26182900 | E36: 0866825139 tiểu tư
B37: TUẦN 4/10 | C37: 30036000
B38: tuần 5/10 | C38: 20613400 | E38: HUYỀN
A39: HỒNG NGỰ | B39: tuần 4/6 | C39: thanh toán rồi | D39: 79664300
B40: tuần 2/10 | C40: TTR | D40: =SUM(C40:C43) -> 143493800
B41: TUẦN 3/10 | C41: TTR | E41: 02776500995 hân
B42: TUẦN 4/10 | C42: 66569800 | E42: X
B43: tuần 5/10 | C43: 76924000 | E43: HUYỀN'
A44: tân hồng | B44: tuần 3/9 | C44: =32104200-15939100 -> 16165100 | D44: =sum(C44:C50) -> 223622600
...

Sheet THÁNG 11
A2: BẢNG CÔNG NỢ THÁNG 11
A3: CHI NHÁNH | C3: SỐ TIỀN | D3: CÔNG NỢ THÁNG
A4: Chợ lách | B4: TUẦN 1 T11 | C4: TTR | D4: =sum(C4:C7) -> 25077500
B5: TUẦN 2 | C5: TTR
B6: TUẦN 3/11 | C6: 20981500 | E6: 0352909819 lương quang
B7: TUẦN 4/11 | C7: 4096000 | E7: NHI
A8: Cái bè | B8: THÁNG 9 + 10 | C8: =sum(77930000-38840000) -> 39090000 | D8: =sum(C8:C12) -> 72404000
B9: TUẦN 1 T11 | C9: 5413600
B10: TUẦN 2 | C10: 10610400 | E10: 0989969719 minh thiện
B11: TUẦN 3/11 | C11: 8745000
B12: TUẦN 4/11 | C12: 8545000 | E12: NHI
A13: Cai lậy | B13: THÁNG 7 | C13: 15200000 | D13: =sum(C13:C17) -> 79800000
B14: THÁNG 8 | C14: 19000000
B15: THÁNG 9 | C15: 15200000 | E15: 0868762644 thiện
B16: THÁNG 10 | C16: 15200000
B17: THÁNG 11 | C17: 15200000
A18: Tân an | B18: TUẦN 2 | C18: TTR | D18: =sum(C20) -> 25290000 | E18: 0937743386 hà nhung
B19: TUẦN 3 | C19: TTR
B20: TUẦN 4 | C20: 25290000 | E20: NHI
A21: Thanh bình | B21: TUẦN 1 T11 | C21: TTR | D21: =sum(C21:C24) -> 63333000 | E21: đơn 118.386 tt 121.591
B22: TUẦN 2 | C22: TTR | E22: còn đơn khai trương
B23: TUẦN 3 | C23: TTR
B24: TUẦN 4 | C24: 63333000 | E24: NHI
A25: Tân bình | B25: TUẦN 1 T11 | C25: TTR | D25: =sum(C25:C28) -> 18310000
B26: TUẦN 2 | C26: 4401000
B27: TUẦN 3 | C27: 10118000
B28: TUẦN 4 | C28: 3791000
E29: 0368930139 tiểu tư
A30: An long | B30: THÁNG 10 | C30: TTR | D30: =sum(C30:C34) -> 56020000
B31: TUẦN 1 T11 | C31: TTR | E31: 0866825139 tiểu tư
B32: TUẦN 2 | C32: TTR
B33: TUẦN 3 | C33: 32163500
B34: TUẦN 4 | C34: 23856500
A35: Hồng ngự | B35: tuần 4/6 | C35: thanh toán rồi | D35: 79664300
B36: TUẦN 1 T11 | C36: TTR | D36: =SUM(C36:C39) -> 109889000
B37: TUẦN 2 | C37: TTR | E37: 02776500995 hân
B38: TUẦN 3 | C38: TTR
B39: TUẦN 4 | C39: 109889000 | E39: HUYỀN'
A40: Tân hồng | B40: THÁNG 10 | C40: =SUM(113622600-40000000) -> 73622600 | D40: =SUM(C40:C44) -> 215039000
B41: TUẦN 1/11 | C41: 31978800
...

Sheet TRINH
A2: BẢNG CÔNG NỢ THÁNG 1
A3: CHI NHÁNH | C3: SỐ TIỀN | D3: CÔNG NỢ THÁNG
A4: VĨNH HƯNG | B4: TUẦN 1/6 | C4: TTR | D4: 27324000
B5: TUẦN 2/6 | C5: 27324000
E7: 0848606139
A9: BÌNH MINH | B9: TUẦN 1/6 | C9: 64772200 | D9: =sum(C9:C10) -> 116562700
B10: TUẦN 2/6 | C10: 51790500
E13: 0854647479
A15: THẠNH PHÚ | B15: TUẦN 2/5 | C15: TTR | D15: =sum(C16:C19) -> 128566800
B16: TUÂN 3/5 | C16: 26704000
B17: TUÂN 4/5 | C17: 41826700
B18: TUẦN 1/6 | C18: 29016600
B19: TUẦN 2/6 | C19: 31019500 | E19: 0878863939
A23: GÒ QUAO | B23: TUÂN 4/5 | C23: TTR | D23: 48827500
B24: TUẦN 2/6 | C24: 48827500
A29: TÂN CHÂU AG | B29: TUÂN 4/5 | C29: 83997200 | D29: =sum(C29:C31) -> 275917000
B30: TUẦN 1/6 | C30: 127631500
B31: TUẦN 2/6 | C31: 64288300
A37: BÌNH TÂN | B37: TUẦN 1/6 | C37: TTR | D37: 39349500
B38: TUẦN 2/6 | C38: 42631500
A43: Giồng riềng | B43: TUÂN 3/5 | C43: TTR | D43: =sum(C44:C46) -> 248375000
B44: TUÂN 4/5 | C44: 91308200
B45: TUẦN 1/6 | C45: 78582300
B46: TUẦN 2/6 | C46: 78484500
A50: TAM BÌNH | B50: TUẦN 1/6 | C50: TTR | D50: 40356500
B51: TUẦN 2/6 | C51: 40356500
E52: 0706750296
A55: CHÂU THÀNH | B55: dh ngày 25/5 | C55: 300000 | D55: =sum(C55:C57) -> 218413000
B56: TUẦN 1/6 | C56: 210723000 | E56: 0376408424
B57: TUẦN 2/6 | C57: 7390000
A60: HẬU NGHĨA
A64: CÁI NƯỚC | B64: TUẦN 4/4 | C64: 36550000 | D64: =sum(C64:C70) -> 190061600
B65: TUẦN 5/4 | C65: 0
B66: TUẦN 1/5 | C66: 23416500
B67: TUẦN 2/5 | C67: 35406600
B68: TUÂN 3/5 | C68: 39045500
B69: TUÂN 4/5 | C69: 22377000
B70: TUẦN 2/6 | C70: 33266000
A73: AN PHONG | B73: TUÂN 3/5 | C73: 4448000 | D73: =sum(C73:C75) -> 49624000 | E73: 0357838131 (Tiểu Tư)
B74: TUẦN 1/6 | C74: 40611000
...

Sheet CHUYẾN XE
B1: TỔNG KHO YAGAMI CAO LÃNH
B2: THỨ 2 | C2: THỨ 3 | D2: THỨ 4 | E2: THỨ 5 | F2: THỨ 6 | G2: THỨ 7 | H2: CHỦ NHẬT | I2: GỬI XE NGOÀI | K2: TRINH
B3: THANH BÌNH | C3: THẠNH PHÚ | D3: LONG XUYÊN | E3: THỐT NỐT | F3: CÀ MAU | G3: KHO BD (HÀNG ĐÔNG) | H3: KHO BD (SÚP) | I3: CÁI TÀU | K3: SANG
B4: AN LONG | C4: BA TRI | D4: RẠCH GIÁ | E4: LẤP VÒ | F4: PHƯỚC LONG | G4: KIẾN TƯỜNG | I4: HÒA PHÚ | K4: HUYỀN
B5: HỒNG NGỰ | C5: BÌNH ĐẠI | D5: KIÊN LƯƠNG | E5: CỜ ĐỎ | F5: NĂM CĂN | G5: THẠNH HOÁ | I5: LAI VUNG | K5: THÚY
B6: TÂN HỒNG | C6: MỎ CÀY | D6: TRI TÔN | E6: VỊ THANH | F6: GIÁ RAI | G6: ĐỨC HUỆ | I6: ĐẠI HỌC
B7: TAM NÔNG | C7: CÁI BÈ | D7: THOẠI SƠN | E7: THỚI LAI | F7: SÔNG ĐỐC | G7: TÂN THẠNH | I7: HAKIMI VL
B8: TÂN HƯNG | C8: CAI LẬY | D8: NHÀ BÀNG | E8: MỘT NGÀN | F8: ĐẦM DƠI | G8: THÁP MƯỜI | I8: XÉM NƯỚNG
B9: VĨNH HƯNG | C9: MỸ THO | D9: HÒN ĐẤT | E9: TRUNG AN | F9: THỚI BÌNH | G9: TRƯỜNG XUÂN | I9: ÔNG BẦU
B10: AN PHONG | C10: CHỢ GẠO | D10: AN CHÂU | E10: Ô MÔN | F10: NGAN DỪA | G10: PHÚ TÂN | I10: TÂN BÌNH
B11: BÌNH MINH | C11: VĨNH BÌNH | D11: TÂN HIỆP | E11: NÀNG MAU | F11: CÁI NƯỚC | G11: CHỢ MỚI | I11: TÂN THÀNH
B12: BÌNH TÂN | C12: GÒ CÔNG | D12: PHÚ HÒA | E12: PHONG ĐIỀN | F12: AN BIÊN | G12: MỸ LUÔNG | I12: PHÚ QUỐC
B13: TAM BÌNH | C13: GÒ ĐEN | D13: AN PHÚ | E13: TIÊU CẦN | F13: VĨNH THUẬN | G13: LONG MỸ | I13: CAO LÃNH
B14: VĨNH LONG | C14: CẦN ĐƯỚC | D14: CHÂU PHÚ | E14: TRÀ ÔN | F14: NGÃ 7 | G14: NGÃ 5 SÓC TRĂNG | I14: CHIBA CAO LÃNH
B15: KẾ SÁCH | C15: TÂN AN | D15: QUỐC THÁI | E15: KHO TRÀ VINH | F15: CÁI TẮC | G15: PHÚ LỘC
B16: MÁI DẦM | C16: TÂN HƯƠNG | D16: GÒ QUAO | E16: TP CẦN THƠ | F16: CHÂU THÀNH - ST | G16: HÒA BÌNH
B17: NGÃ 6 | C17: CHỢ LÁCH | D17: GIỒNG RIỀNG | F17: TRẦN VĂN THỜI | G17: BẠC LIÊU
B18: LONG PHÚ | C18: GIỒNG TRÔM | D18: RẠCH SỎI | F18: T.T THỨ 11 | G18: CHỢ VÀM
B19: VĨNH CHÂU | C19: CHÂU ĐỐC | D19: HÀ TIÊN | F19: TẮC VÂN
B20: TRẦN ĐỀ | C20: CHIBA TÂN CHÂU | D20: VĨNH THẠNH | F20: H.HỮU NGHĨA
B21: AN THẠNH | C21: TÂN CHÂU - AG | D21: CHI LĂNG | F21: PHÚ TÂM
C22: GIA THUẬN | D22: CẦN ĐĂNG | F22: CÂY DƯƠNG
D23: ÓC EO | F23: SÓC TRĂNG
D24: MINH LƯƠNG | F24: SA ĐÉC
F25: GÀNH HÀO
B35: BẢNG XE TẢI KHO BÌNH DƯƠNG
B36: THỨ 2 | C36: THỨ 3 | D36: THỨ 4 | E36: THỨ 5 | F36: THỨ 6
B37: BÀU BÀNG | C37: PHAN RANG | D37: THỐNG NHẤT | E37: NGÃI GIAO | F37: CỦ CHI
B38: CHƠN THÀNH | C38: PHAN THIẾT | D38: ĐỊNH QUÁN | E38: PHÚ MỸ | F38: TRẢNG BÀNG
B39: BÌNH LONG | C39: LAGI | D39: TRẢNG BOM | E39: ĐẠI PHƯỚC | F39: GÒ DẦU
B40: LỘC NINH | C40: XUYÊN MỘC | D40: ĐỨC TRỌNG | E40: LONG THÀNH | F40: PHƯỚC ĐÔNG
B41: PHƯỚC LONG | C41: LONG HẢI | D41: HẬU NGHĨA | E41: TAM PHƯỚC | F41: HÒA THÀNH
B42: ĐỒNG XOÀI | C42: VŨNG TÀU | D42: MỸ HẠNH NAM | E42: AN TÂY | F42: TÂY NINH
B43: DODO | C43: BÀ RỊA | D43: ĐỨC HÒA | E43: MỸ PHƯỚC 1 | F43: DƯƠNG MINH CHÂU
B44: HỘI NGHĨA | D44: BẾN LỨC | E44: TÂN UYÊN | F44: TÂN CHÂU
B45: VĨNH TÂN | D45: QUẬN 12 | E45: THUẬN GIAO | F45: MONO
B46: PHÚ CHÁNH | E46: THỦ DẦU 1
B47: AN TÂY | E47: BÀU BÀNG
B48: MỸ PHƯỚC 1 | E48: PHÚ CHÁNH
B49: TÂN UYÊN | E49: HỘI NGHĨA
...

Sheet THÁNG 1 -2026
A2: BẢNG CÔNG NỢ THÁNG 1
A3: CHI NHÁNH | C3: SỐ TIỀN | D3: CÔNG NỢ THÁNG
A4: Kiến tường | B4: TUẦN 1 | C4: ttr | D4: =sum(C4:C8) -> 42991000
B5: TUẦN 2 | C5: ttr
B6: TUẦN 3 | C6: ttr
B7: TUẦN 4 | C7: ttr
B8: TUẦN 5 | C8: 42991000
A9: Phú tân | B9: TUẦN 1 | D9: =sum(C9:C12) -> 29481000 | E9: 0984255034 vũ
B10: TUẦN 2 | C10: =SUM(33946000-7165000) -> 26781000
B11: TUẦN 3
B12: TUẦN 4 | C12: 2700000
A13: Chợ mới | B13: TUẦN 1 | C13: TTR | D13: =sum(C13:C16) -> 83320000 | E13: 0932808239 tấn đạt
B14: TUẦN 2 | C14: TTR
B15: TUẦN 3 | C15: TTR
B16: TUẦN 4 | C16: 83320000
A17: Mỹ luông | B17: T12 | C17: TTR | D17: =sum(C17:C22) -> 9194000
B18: TUẦN 1
B19: TUẦN 2 | C19: TTR
B20: TUẦN 3 | C20: TTR
B21: TUẦN 4 | C21: TTR
B22: TUẦN 5 | C22: 9194000 | E22: 04916040949 diệu hiền
A23: Long xuyên | B23: KHÔ TẾT | C23: 29700000 | D23: =sum(C23:C29) -> 113025000
B24: ĐÔNG TẾT
B25: T12 | C25: 60000000
B26: TUẦN 1 | C26: 0
B27: TUẦN 2 | C27: 0
B28: TUẦN 3 | C28: 0
B29: TUẦN 4 | C29: 23325000
A30: Ngã 7 | B30: THÁNG 10 | C30: 40000000 | D30: =sum(C30:C34) -> 110225000 | E30: 0977727797 duyên
B31: ĐH 19/12 | C31: 20620000
B32: ĐH 2/1 | C32: 16351000
B33: ĐH 16/1(TRỪ 22TH GIẤY) | C33: =SUM(16140000- 66000) -> 16074000
B34: DH 30/1 | C34: 17180000
A35: Châu đốc | B35: KHÔ TẾT | C35: 151330000 | D35: =sum(C35:C41) -> 371766500
B36: ĐÔNG TẾT
B37: TUẦN 1
B38: TUẦN 2 | C38: 92528000 | E38: 0777846226 lộc
B39: TUẦN 3 | C39: 44406500
B40: TUẦN 4 | C40: 42541000
B41: TUẦN 5 | C41: 40961000
...

Sheet THÁNG 2 (PHƯỢNG)
A2: BẢNG CÔNG NỢ THÁNG 4
A3: CHI NHÁNH | C3: SỐ TIỀN | D3: CÔNG NỢ THÁNG
A4: TT THỨ 11 | B4: THÁNG 5 | C4: 93228500 | D4: =SUM(C4:C7) -> 199660000
B5: ĐH TUẦN 1 T6 | C5: 56454500 | E5: =63*3000+70000 -> 259000
B6: ĐH TUẦN 2 T6 | C6: 49977000
A8: TP CẦN THƠ | B8: ĐH TUẦN 1 T6 | C8: R | D8: =SUM(C8:C11) -> 151498000
B9: ĐH TUẦN 2 T6 | C9: 151498000
A12: AN THẠNH | B12: ĐH TUẦN 1 T6 | C12: R | D12: =SUM(C12:C15) -> 45587800
B13: ĐH TUẦN 2 T6 | C13: 45587800
A16: PHÚ TÂM | B16: ĐH TUẦN 4 T5 | C16: R | D16: =SUM(C16:C19) -> 29530000
B17: ĐH TUẦN 1 T6 | C17: R
B18: ĐH TUẦN 2 T6 | C18: 29530000
A20: PHÚ LỘC | B20: ĐH TUẦN 1 T5 | C20: 153867400 | D20: =SUM(C20:C23) -> 229363900
B21: ĐH TUẦN 1 T6 | C21: 42946500
B22: ĐH TUẦN 2 T6 | C22: 32550000
A24: TRƯỜNG XUÂN | B24: ĐH TUẦN 1 T6 | C24: 52999500 | D24: =SUM(C24:C27) -> 79564500
B25: ĐH TUẦN 2 T6 | C25: 26565000
A28: CHỢ VÀM | B28: ĐH TUẦN 2 T6 | C28: 36695500 | D28: =SUM(C28:C31) -> 36695500
A32: GIỒNG TRÔM | B32: ĐH TUẦN 4 T5 | C32: R | D32: =SUM(C32:C35) -> 42275500
B33: ĐH TUẦN 1 T6 | C33: R
B34: ĐH TUẦN 2 T6 | C34: 42275500
A36: QUÁN LẨU A LONG | B36: ĐH THÁNG 5 | C36: 163753100 | D36: =SUM(C36:C39) -> 192994800
B37: ĐH TUẦN 1 T6 | C37: 29241700
A40: CHIBA TÂN CHÂU | B40: ĐH TUẦN 1 T6 | C40: 90372800 | D40: =SUM(C40:C43) -> 158987300
B41: ĐH TUẦN 2 T6 | C41: 68614500
A44: CÂY DƯƠNG | B44: ĐH TUẦN 4 T5 | C44: 32368000 | D44: =SUM(C44:C47) -> 120172500
B45: ĐH TUẦN 1 T6 | C45: 44384000
B46: ĐH TUẦN 2 T6 | C46: 43420500
A48: GIA THUẬN | D48: =SUM(C48:C51) -> 0
A55: ĐƠN HÀNG KHAI TRƯƠNG
A56: ĐƠN KHAI TRƯƠNG PHƯỚC ĐÔNG | B56: ĐƠN KHAI TRƯƠNG | C56: 564712000
B57: Thanh toán 17/1 | C57: -150000000
C58: -414712000
B61: ĐƠN HÀNG CÒN LẠI | C61: =Sum(C56:C60) -> 0
A62: ĐƠN KHAI TRƯƠNG MINH LƯƠNG | B62: ĐƠN KHAI TRƯƠNG | C62: 1539090000
B63: Thanh toán | C63: -1539090000
B64: ĐƠN HÀNG CÒN LẠI | C64: =Sum(C62:C63) -> 0
A65: ĐƠN KHAI TRƯƠNG PHÚ CHÁNH | B65: ĐƠN KHAI TRƯƠNG | C65: 807705000
B66: Thanh toán 31/10 | C66: -300000000
B67: Thanh toán 31/10 | C67: -200000000
...

Sheet Ngọc Sang
A2: BẢNG CÔNG NỢ THÁNG 1
A3: CHI NHÁNH | C3: SỐ TIỀN | D3: CÔNG NỢ THÁNG
A4: Chợ lách | B4: T5 | C4: ttr | D4: =sum(C4:C8) -> 32994000 | E4: 0352909819 lương quang
B5: TUẦN 1 | C5: ttr
B6: TUẦN 2 | C6: 32994000
B7: TUẦN 3
B8: TUẦN 4
A9: Cái bè | B9: THÁNG 5 | C9: 105359400 | D9: =sum(C9:C14) -> 160294100 | E9: 0989969719 minh thiện
B10: THÁNG 4 | C10: ttr
B11: TUẦN 1 | C11: 29939000
B12: TUẦN 2 | C12: 24995700
B13: TUẦN 3
B14: TUẦN 4
A15: Cai lậy | B15: THÁNG 2 | C15: 7600000 | D15: =sum(C15:C22) -> 63200000 | E15: 0868762644 thiện
B16: THÁNG 3 | C16: 16600000
B17: THÁNG 4 | C17: 15600000
B18: THÁNG 5 | C18: 15600000
B19: TUẦN 1 | C19: 0
B20: TUẦN 2 | C20: 7800000
B21: TUẦN 3
B22: TUẦN 4
A23: Tân an | B23: THÁNG 5 | C23: ttr | D23: =SUM(C23:C27) -> 23165000 | E23: 0937743386 hà nhung
B24: TUẦN 1 | C24: ttr
B25: TUẦN 2 | C25: 23165000
B26: TUẦN 3
B27: TUẦN 4
A28: Thanh bình | B28: TUẦN 1 | C28: TTR | D28: =sum(C28:C32) -> 55600000
B29: TUẦN 2 | C29: 55600000
B30: TUẦN 3 | C30: TTR
B31: TUẦN 4 | C31: TTR
B32: TUẦN 5
A33: Tân bình | B33: THÁNG 4 | C33: TTR | D33: =sum(C33:C37) -> 33970500
B34: TUẦN 1 | C34: 31600500 | E34: 0368930139 tiểu tư
B35: TUẦN 2 | C35: 2370000
B36: TUẦN 3
B37: TUẦN 4
A38: An long | B38: THÁNG 5 | C38: 10000000 | D38: =sum(C38:C42) -> 56636700
B39: TUẦN 1 | C39: 26136700 | E39: 0866825139 tiểu tư
B40: TUẦN 2 | C40: 20500000
B41: TUẦN 3
...

Sheet THÁNG 6 -2026 (HÍ NÈ)
A2: BẢNG CÔNG NỢ THÁNG 6
A3: CHI NHÁNH | C3: SỐ TIỀN | D3: CÔNG NỢ THÁNG
A4: TIỂU CẦN | B4: TUẦN 4/5 | C4: TTR | D4: =SUM(C4:C7) -> 67926000
B5: TUẦN 1/6 | C5: TTR
B6: TUẦN 2/6 | C6: 67926000 | E6: THÚY
E7: 0898507736
A8: GÀNH HÀO | B8: TUẦN 1/5 | C8: TTR | D8: =SUM(C8:C13) -> 58817500
B9: TUẦN 2/5 | C9: TTR
B10: TUẦN 3/5 | C10: TTR
B11: TUẦN 4/5 | C11: TTR
B12: TUẦN 1/6 | C12: 22880000 | E12: THÚY
B13: TUẦN 2/6 | C13: 35937500
A14: HÒA BÌNH | B14: TUẦN 1/6 | C14: TTR | D14: =SUM(C14:C18) -> 43138000
B15: TUẦN 2/6 | C15: 43138000
E16: THÚY
A19: AN CHÂU | B19: TUẦN 2/5 | C19: TTR | D19: =SUM(C19:C24) -> 143858500
B20: TUẦN 3/5 | C20: TTR
B21: TUẦN 4/5 | C21: TTR
B22: TUẦN 1/6 | C22: 68732500 | E22: THÚY
B23: TUẦN 2/6 | C23: 75126000
E24: 0767999279
A25: TÂN HIỆP | B25: TUẦN 4/5 | C25: TTR | D25: =SUM(C25:C29) -> 39634500
B26: TUẦN 1/6 | C26: TTR
B27: TUẦN 2/6 | C27: 39634500
E28: THÚY
E29: 0798 002 686 thuận
A30: NÀNG MAU | B30: THÁNG 1 | C30: =66696500-30000000 -> 36696500 | D30: =sum(C30:C35) -> 68114500
B31: TUẦN 3/5 | C31: TTR
B32: TUẦN 4/5 | C32: TTR
B33: TUẦN 1/6 | C33: 31418000
E35: THÚY
A36: CHỢ GẠO | B36: TUẦN 2/5 | C36: TTR | D36: =SUM(C36:C41) -> 33552500
B37: TUẦN 4/5 | C37: TTR | E37: trả mỗi tuần, k cần xuất công nợ
B38: TUẦN 1/6 | C38: 33552500
E40: 070.4888.980 nhân
E41: THÚY
A42: ĐẦM DƠI | B42: TUẦN 4/4 | C42: TTR | D42: =sum(C42:C47) -> 70631000
B43: TUẦN 1/5 | C43: TTR
B44: TUÀN 3/5 | C44: TTR
B45: TUẦN 4/5 | C45: 19054600
...

Sheet DANH SÁCH CHI NHÁNH MƯỢN TỦ MÁT
B3: DS CHI NHÁNH MƯỢN TỦ MÁT
B4: STT | C4: TÊN CHI NHÁNH | D4: NGÀY MƯỢN | E4: NGÀY TRẢ
B5: 1 | C5: CHÂU PHÚ | D5: 45665 | F5: mua
B6: 2 | C6: THÁP MƯỜI | D6: 45669 | E6: 45710 | F6: trả về
B7: 3 | C7: sóc trăng | D7: 45670 | E7: Mua
B8: 4 | C8: MỸ THO | D8: 45671 | E8: mua | H8: =1200/30 -> 40
B9: 5 | C9: tân châu | D9: 45672 | E9: 45721 | H9: =40*10 -> 400
B10: 6 | C10: Thốt Nốt | D10: 45675 | H10: =1200+400 -> 1600 | J10: 33 QUẢN LÝ XÁM
B11: 7 | C11: Sông Đốc | D11: 45675 | E11: 45710 | F11: trả về | J11: 30 ÁO VÀNG TAY TRẮNG
B12: 8 | C12: Lai Vung | D12: 45677 | E12: 45725 | F12: trả về | J12: 36 ĐEN VIỀN ĐỎ
B13: 9 | C13: Vũng Tàu | D13: 45677 | E13: 45727 | F13: trả về | J13: 222 ĐEN VIỀN VÀNG
B14: 10 | C14: Rạch giá | D14: 45678 | F14: trả về | J14: 30 ÁO ĐỎ TAY TRẮNG
B15: 11
B16: 12
B17: 13
B18: 14
B19: 15
B23: CHI NHÁNH | C23: bao lì xì
B24: BẾN TRE
B25: CÁI BÈ
B26: CAI LẬY
B27: TÂN AN
B28: THỦ ĐỨC
B29: THANH BÌNH
B30: TÂN BÌNH | C30: Đã giao
B31: AN LONG
B32: BÚN ĐẬU
B33: HỒNG NGỰ
B34: TÂN HỒNG
B35: TAM NÔNG
B36: LONG MỸ
B37: NGÃ 5 - SÓC TRĂNG
B38: SA ĐÉC
B39: LONG XUYÊN
B40: CÁI TÀU HẠ | C40: đã giao
B41: LẤP VÒ
B42: ĐẠI HỌC
B43: TRÀ ÔN
B44: MỸ THO
B45: VỊ THANH
...
