Workbook

Sheet TONG_HOP_NGAY
A1: TỔNG HỢP THEO NGÀY
A2: Ngày | B2: Tồn đầu | C2: Nhập | D2: Xuất | E2: Điều chỉnh +/- | F2: Tồn cuối | G2: Tồn thực tế | H2: Dư/Thiếu | I2: Lệch trong ngày | J2: Trạng thái | K2: Ghi chú
A3: 46292 | B3: 129 | C3: =SUMIFS(GIAO_DICH!$F$4:$F$13581,GIAO_DICH!$B$4:$B$13581,">="&A3,GIAO_DICH!$B$4:$B$13581,"<"&A3+1,GIAO_DICH!$F$4:$F$13581,">0",GIAO_DICH!$C$4:$C$13581,"<>Kiểm hàng") -> 70 | D3: =-SUMIFS(GIAO_DICH!$F$4:$F$13581,GIAO_DICH!$B$4:$B$13581,">="&A3,GIAO_DICH!$B$4:$B$13581,"<"&A3+1,GIAO_DICH!$F$4:$F$13581,"<0",GIAO_DICH!$C$4:$C$13581,"<>Kiểm hàng") -> 73 | E3: =SUMIFS(GIAO_DICH!$F$4:$F$13581,GIAO_DICH!$B$4:$B$13581,">="&A3,GIAO_DICH!$B$4:$B$13581,"<"&A3+1,GIAO_DICH!$C$4:$C$13581,"Kiểm hàng") -> 0 | F3: =B3+C3-D3+E3 -> 126 | G3: 126 | H3: =IF(G3="","",G3-F3) -> 0 | I3: =IF(H3="","",H3) -> 0 | J3: =IF(G3="","CHƯA KIỂM",IF(H3=0,"KHỚP",IF(H3>0,"DƯ","THIẾU"))) -> KHỚP
A4: 46293 | B4: =F3 -> 126 | C4: =SUMIFS(GIAO_DICH!$F$4:$F$13581,GIAO_DICH!$B$4:$B$13581,">="&A4,GIAO_DICH!$B$4:$B$13581,"<"&A4+1,GIAO_DICH!$F$4:$F$13581,">0",GIAO_DICH!$C$4:$C$13581,"<>Kiểm hàng") -> 0 | D4: =-SUMIFS(GIAO_DICH!$F$4:$F$13581,GIAO_DICH!$B$4:$B$13581,">="&A4,GIAO_DICH!$B$4:$B$13581,"<"&A4+1,GIAO_DICH!$F$4:$F$13581,"<0",GIAO_DICH!$C$4:$C$13581,"<>Kiểm hàng") -> 2 | E4: =SUMIFS(GIAO_DICH!$F$4:$F$13581,GIAO_DICH!$B$4:$B$13581,">="&A4,GIAO_DICH!$B$4:$B$13581,"<"&A4+1,GIAO_DICH!$C$4:$C$13581,"Kiểm hàng") -> 0 | F4: =B4+C4-D4+E4 -> 124 | G4: 124 | H4: =IF(G4="","",G4-F4) -> 0 | I4: =IF(H4="","",H4-H3) -> 0 | J4: =IF(G4="","CHƯA KIỂM",IF(H4=0,"KHỚP",IF(H4>0,"DƯ","THIẾU"))) -> KHỚP
A5: 46294 | B5: =F4 -> 124 | C5: =SUMIFS(GIAO_DICH!$F$4:$F$13581,GIAO_DICH!$B$4:$B$13581,">="&A5,GIAO_DICH!$B$4:$B$13581,"<"&A5+1,GIAO_DICH!$F$4:$F$13581,">0",GIAO_DICH!$C$4:$C$13581,"<>Kiểm hàng") -> 0 | D5: =-SUMIFS(GIAO_DICH!$F$4:$F$13581,GIAO_DICH!$B$4:$B$13581,">="&A5,GIAO_DICH!$B$4:$B$13581,"<"&A5+1,GIAO_DICH!$F$4:$F$13581,"<0",GIAO_DICH!$C$4:$C$13581,"<>Kiểm hàng") -> 6 | E5: =SUMIFS(GIAO_DICH!$F$4:$F$13581,GIAO_DICH!$B$4:$B$13581,">="&A5,GIAO_DICH!$B$4:$B$13581,"<"&A5+1,GIAO_DICH!$C$4:$C$13581,"Kiểm hàng") -> 0 | F5: =B5+C5-D5+E5 -> 118 | G5: 118 | H5: =IF(G5="","",G5-F5) -> 0 | I5: =IF(H5="","",H5-H4) -> 0 | J5: =IF(G5="","CHƯA KIỂM",IF(H5=0,"KHỚP",IF(H5>0,"DƯ","THIẾU"))) -> KHỚP
A6: 46295 | B6: =F5 -> 118 | C6: =SUMIFS(GIAO_DICH!$F$4:$F$13581,GIAO_DICH!$B$4:$B$13581,">="&A6,GIAO_DICH!$B$4:$B$13581,"<"&A6+1,GIAO_DICH!$F$4:$F$13581,">0",GIAO_DICH!$C$4:$C$13581,"<>Kiểm hàng") -> 0 | D6: =-SUMIFS(GIAO_DICH!$F$4:$F$13581,GIAO_DICH!$B$4:$B$13581,">="&A6,GIAO_DICH!$B$4:$B$13581,"<"&A6+1,GIAO_DICH!$F$4:$F$13581,"<0",GIAO_DICH!$C$4:$C$13581,"<>Kiểm hàng") -> 29 | E6: =SUMIFS(GIAO_DICH!$F$4:$F$13581,GIAO_DICH!$B$4:$B$13581,">="&A6,GIAO_DICH!$B$4:$B$13581,"<"&A6+1,GIAO_DICH!$C$4:$C$13581,"Kiểm hàng") -> 0 | F6: =B6+C6-D6+E6 -> 89 | G6: 89 | H6: =IF(G6="","",G6-F6) -> 0 | I6: =IF(H6="","",H6-H5) -> 0 | J6: =IF(G6="","CHƯA KIỂM",IF(H6=0,"KHỚP",IF(H6>0,"DƯ","THIẾU"))) -> KHỚP
A7: 46296 | B7: =F6 -> 89 | C7: =SUMIFS(GIAO_DICH!$F$4:$F$13581,GIAO_DICH!$B$4:$B$13581,">="&A7,GIAO_DICH!$B$4:$B$13581,"<"&A7+1,GIAO_DICH!$F$4:$F$13581,">0",GIAO_DICH!$C$4:$C$13581,"<>Kiểm hàng") -> 0 | D7: =-SUMIFS(GIAO_DICH!$F$4:$F$13581,GIAO_DICH!$B$4:$B$13581,">="&A7,GIAO_DICH!$B$4:$B$13581,"<"&A7+1,GIAO_DICH!$F$4:$F$13581,"<0",GIAO_DICH!$C$4:$C$13581,"<>Kiểm hàng") -> 34 | E7: =SUMIFS(GIAO_DICH!$F$4:$F$13581,GIAO_DICH!$B$4:$B$13581,">="&A7,GIAO_DICH!$B$4:$B$13581,"<"&A7+1,GIAO_DICH!$C$4:$C$13581,"Kiểm hàng") -> -5 | F7: =B7+C7-D7+E7 -> 50 | G7: 50 | H7: =IF(G7="","",G7-F7) -> 0 | I7: =IF(H7="","",H7-H6) -> 0 | J7: =IF(G7="","CHƯA KIỂM",IF(H7=0,"KHỚP",IF(H7>0,"DƯ","THIẾU"))) -> KHỚP
A8: 46297 | B8: =F7 -> 50 | C8: =SUMIFS(GIAO_DICH!$F$4:$F$13581,GIAO_DICH!$B$4:$B$13581,">="&A8,GIAO_DICH!$B$4:$B$13581,"<"&A8+1,GIAO_DICH!$F$4:$F$13581,">0",GIAO_DICH!$C$4:$C$13581,"<>Kiểm hàng") -> 0 | D8: =-SUMIFS(GIAO_DICH!$F$4:$F$13581,GIAO_DICH!$B$4:$B$13581,">="&A8,GIAO_DICH!$B$4:$B$13581,"<"&A8+1,GIAO_DICH!$F$4:$F$13581,"<0",GIAO_DICH!$C$4:$C$13581,"<>Kiểm hàng") -> 38 | E8: =SUMIFS(GIAO_DICH!$F$4:$F$13581,GIAO_DICH!$B$4:$B$13581,">="&A8,GIAO_DICH!$B$4:$B$13581,"<"&A8+1,GIAO_DICH!$C$4:$C$13581,"Kiểm hàng") -> 0 | F8: =B8+C8-D8+E8 -> 12 | G8: 15 | H8: =IF(G8="","",G8-F8) -> 3 | I8: =IF(H8="","",H8-H7) -> 3 | J8: =IF(G8="","CHƯA KIỂM",IF(H8=0,"KHỚP",IF(H8>0,"DƯ","THIẾU"))) -> DƯ
A9: 46298 | B9: =F8 -> 12 | C9: =SUMIFS(GIAO_DICH!$F$4:$F$13581,GIAO_DICH!$B$4:$B$13581,">="&A9,GIAO_DICH!$B$4:$B$13581,"<"&A9+1,GIAO_DICH!$F$4:$F$13581,">0",GIAO_DICH!$C$4:$C$13581,"<>Kiểm hàng") -> 200 | D9: =-SUMIFS(GIAO_DICH!$F$4:$F$13581,GIAO_DICH!$B$4:$B$13581,">="&A9,GIAO_DICH!$B$4:$B$13581,"<"&A9+1,GIAO_DICH!$F$4:$F$13581,"<0",GIAO_DICH!$C$4:$C$13581,"<>Kiểm hàng") -> 122 | E9: =SUMIFS(GIAO_DICH!$F$4:$F$13581,GIAO_DICH!$B$4:$B$13581,">="&A9,GIAO_DICH!$B$4:$B$13581,"<"&A9+1,GIAO_DICH!$C$4:$C$13581,"Kiểm hàng") -> 0 | F9: =B9+C9-D9+E9 -> 90 | G9: 85 | H9: =IF(G9="","",G9-F9) -> -5 | I9: =IF(H9="","",H9-H8) -> -8 | J9: =IF(G9="","CHƯA KIỂM",IF(H9=0,"KHỚP",IF(H9>0,"DƯ","THIẾU"))) -> THIẾU
A10: 46299 | B10: =F9 -> 90 | C10: =SUMIFS(GIAO_DICH!$F$4:$F$13581,GIAO_DICH!$B$4:$B$13581,">="&A10,GIAO_DICH!$B$4:$B$13581,"<"&A10+1,GIAO_DICH!$F$4:$F$13581,">0",GIAO_DICH!$C$4:$C$13581,"<>Kiểm hàng") -> 0 | D10: =-SUMIFS(GIAO_DICH!$F$4:$F$13581,GIAO_DICH!$B$4:$B$13581,">="&A10,GIAO_DICH!$B$4:$B$13581,"<"&A10+1,GIAO_DICH!$F$4:$F$13581,"<0",GIAO_DICH!$C$4:$C$13581,"<>Kiểm hàng") -> 2 | E10: =SUMIFS(GIAO_DICH!$F$4:$F$13581,GIAO_DICH!$B$4:$B$13581,">="&A10,GIAO_DICH!$B$4:$B$13581,"<"&A10+1,GIAO_DICH!$C$4:$C$13581,"Kiểm hàng") -> 0 | F10: =B10+C10-D10+E10 -> 88 | G10: 83 | H10: =IF(G10="","",G10-F10) -> -5 | I10: =IF(H10="","",H10-H9) -> 0 | J10: =IF(G10="","CHƯA KIỂM",IF(H10=0,"KHỚP",IF(H10>0,"DƯ","THIẾU"))) -> THIẾU
A11: 46300 | B11: =F10 -> 88 | C11: =SUMIFS(GIAO_DICH!$F$4:$F$13581,GIAO_DICH!$B$4:$B$13581,">="&A11,GIAO_DICH!$B$4:$B$13581,"<"&A11+1,GIAO_DICH!$F$4:$F$13581,">0",GIAO_DICH!$C$4:$C$13581,"<>Kiểm hàng") -> 0 | D11: =-SUMIFS(GIAO_DICH!$F$4:$F$13581,GIAO_DICH!$B$4:$B$13581,">="&A11,GIAO_DICH!$B$4:$B$13581,"<"&A11+1,GIAO_DICH!$F$4:$F$13581,"<0",GIAO_DICH!$C$4:$C$13581,"<>Kiểm hàng") -> 0 | E11: =SUMIFS(GIAO_DICH!$F$4:$F$13581,GIAO_DICH!$B$4:$B$13581,">="&A11,GIAO_DICH!$B$4:$B$13581,"<"&A11+1,GIAO_DICH!$C$4:$C$13581,"Kiểm hàng") -> 0 | F11: =B11+C11-D11+E11 -> 88 | H11: =IF(G11="","",G11-F11) | I11: =IF(H11="","",H11-H10) | J11: =IF(G11="","CHƯA KIỂM",IF(H11=0,"KHỚP",IF(H11>0,"DƯ","THIẾU"))) -> CHƯA KIỂM
A12: 46301 | B12: =F11 -> 88 | C12: =SUMIFS(GIAO_DICH!$F$4:$F$13581,GIAO_DICH!$B$4:$B$13581,">="&A12,GIAO_DICH!$B$4:$B$13581,"<"&A12+1,GIAO_DICH!$F$4:$F$13581,">0",GIAO_DICH!$C$4:$C$13581,"<>Kiểm hàng") -> 0 | D12: =-SUMIFS(GIAO_DICH!$F$4:$F$13581,GIAO_DICH!$B$4:$B$13581,">="&A12,GIAO_DICH!$B$4:$B$13581,"<"&A12+1,GIAO_DICH!$F$4:$F$13581,"<0",GIAO_DICH!$C$4:$C$13581,"<>Kiểm hàng") -> 0 | E12: =SUMIFS(GIAO_DICH!$F$4:$F$13581,GIAO_DICH!$B$4:$B$13581,">="&A12,GIAO_DICH!$B$4:$B$13581,"<"&A12+1,GIAO_DICH!$C$4:$C$13581,"Kiểm hàng") -> 0 | F12: =B12+C12-D12+E12 -> 88 | H12: =IF(G12="","",G12-F12) | I12: =IF(H12="","",H12-H11) | J12: =IF(G12="","CHƯA KIỂM",IF(H12=0,"KHỚP",IF(H12>0,"DƯ","THIẾU"))) -> CHƯA KIỂM
A13: 46302 | B13: =F12 -> 88 | C13: =SUMIFS(GIAO_DICH!$F$4:$F$13581,GIAO_DICH!$B$4:$B$13581,">="&A13,GIAO_DICH!$B$4:$B$13581,"<"&A13+1,GIAO_DICH!$F$4:$F$13581,">0",GIAO_DICH!$C$4:$C$13581,"<>Kiểm hàng") -> 0 | D13: =-SUMIFS(GIAO_DICH!$F$4:$F$13581,GIAO_DICH!$B$4:$B$13581,">="&A13,GIAO_DICH!$B$4:$B$13581,"<"&A13+1,GIAO_DICH!$F$4:$F$13581,"<0",GIAO_DICH!$C$4:$C$13581,"<>Kiểm hàng") -> 0 | E13: =SUMIFS(GIAO_DICH!$F$4:$F$13581,GIAO_DICH!$B$4:$B$13581,">="&A13,GIAO_DICH!$B$4:$B$13581,"<"&A13+1,GIAO_DICH!$C$4:$C$13581,"Kiểm hàng") -> 0 | F13: =B13+C13-D13+E13 -> 88 | H13: =IF(G13="","",G13-F13) | I13: =IF(H13="","",H13-H12) | J13: =IF(G13="","CHƯA KIỂM",IF(H13=0,"KHỚP",IF(H13>0,"DƯ","THIẾU"))) -> CHƯA KIỂM
A14: 46303 | B14: =F13 -> 88 | C14: =SUMIFS(GIAO_DICH!$F$4:$F$13581,GIAO_DICH!$B$4:$B$13581,">="&A14,GIAO_DICH!$B$4:$B$13581,"<"&A14+1,GIAO_DICH!$F$4:$F$13581,">0",GIAO_DICH!$C$4:$C$13581,"<>Kiểm hàng") -> 0 | D14: =-SUMIFS(GIAO_DICH!$F$4:$F$13581,GIAO_DICH!$B$4:$B$13581,">="&A14,GIAO_DICH!$B$4:$B$13581,"<"&A14+1,GIAO_DICH!$F$4:$F$13581,"<0",GIAO_DICH!$C$4:$C$13581,"<>Kiểm hàng") -> 0 | E14: =SUMIFS(GIAO_DICH!$F$4:$F$13581,GIAO_DICH!$B$4:$B$13581,">="&A14,GIAO_DICH!$B$4:$B$13581,"<"&A14+1,GIAO_DICH!$C$4:$C$13581,"Kiểm hàng") -> 0 | F14: =B14+C14-D14+E14 -> 88 | H14: =IF(G14="","",G14-F14) | I14: =IF(H14="","",H14-H13) | J14: =IF(G14="","CHƯA KIỂM",IF(H14=0,"KHỚP",IF(H14>0,"DƯ","THIẾU"))) -> CHƯA KIỂM
A15: 46304 | B15: =F14 -> 88 | C15: =SUMIFS(GIAO_DICH!$F$4:$F$13581,GIAO_DICH!$B$4:$B$13581,">="&A15,GIAO_DICH!$B$4:$B$13581,"<"&A15+1,GIAO_DICH!$F$4:$F$13581,">0",GIAO_DICH!$C$4:$C$13581,"<>Kiểm hàng") -> 0 | D15: =-SUMIFS(GIAO_DICH!$F$4:$F$13581,GIAO_DICH!$B$4:$B$13581,">="&A15,GIAO_DICH!$B$4:$B$13581,"<"&A15+1,GIAO_DICH!$F$4:$F$13581,"<0",GIAO_DICH!$C$4:$C$13581,"<>Kiểm hàng") -> 0 | E15: =SUMIFS(GIAO_DICH!$F$4:$F$13581,GIAO_DICH!$B$4:$B$13581,">="&A15,GIAO_DICH!$B$4:$B$13581,"<"&A15+1,GIAO_DICH!$C$4:$C$13581,"Kiểm hàng") -> 0 | F15: =B15+C15-D15+E15 -> 88 | H15: =IF(G15="","",G15-F15) | I15: =IF(H15="","",H15-H14) | J15: =IF(G15="","CHƯA KIỂM",IF(H15=0,"KHỚP",IF(H15>0,"DƯ","THIẾU"))) -> CHƯA KIỂM
A16: 46305 | B16: =F15 -> 88 | C16: =SUMIFS(GIAO_DICH!$F$4:$F$13581,GIAO_DICH!$B$4:$B$13581,">="&A16,GIAO_DICH!$B$4:$B$13581,"<"&A16+1,GIAO_DICH!$F$4:$F$13581,">0",GIAO_DICH!$C$4:$C$13581,"<>Kiểm hàng") -> 0 | D16: =-SUMIFS(GIAO_DICH!$F$4:$F$13581,GIAO_DICH!$B$4:$B$13581,">="&A16,GIAO_DICH!$B$4:$B$13581,"<"&A16+1,GIAO_DICH!$F$4:$F$13581,"<0",GIAO_DICH!$C$4:$C$13581,"<>Kiểm hàng") -> 0 | E16: =SUMIFS(GIAO_DICH!$F$4:$F$13581,GIAO_DICH!$B$4:$B$13581,">="&A16,GIAO_DICH!$B$4:$B$13581,"<"&A16+1,GIAO_DICH!$C$4:$C$13581,"Kiểm hàng") -> 0 | F16: =B16+C16-D16+E16 -> 88 | H16: =IF(G16="","",G16-F16) | I16: =IF(H16="","",H16-H15) | J16: =IF(G16="","CHƯA KIỂM",IF(H16=0,"KHỚP",IF(H16>0,"DƯ","THIẾU"))) -> CHƯA KIỂM
A17: 46306 | B17: =F16 -> 88 | C17: =SUMIFS(GIAO_DICH!$F$4:$F$13581,GIAO_DICH!$B$4:$B$13581,">="&A17,GIAO_DICH!$B$4:$B$13581,"<"&A17+1,GIAO_DICH!$F$4:$F$13581,">0",GIAO_DICH!$C$4:$C$13581,"<>Kiểm hàng") -> 0 | D17: =-SUMIFS(GIAO_DICH!$F$4:$F$13581,GIAO_DICH!$B$4:$B$13581,">="&A17,GIAO_DICH!$B$4:$B$13581,"<"&A17+1,GIAO_DICH!$F$4:$F$13581,"<0",GIAO_DICH!$C$4:$C$13581,"<>Kiểm hàng") -> 0 | E17: =SUMIFS(GIAO_DICH!$F$4:$F$13581,GIAO_DICH!$B$4:$B$13581,">="&A17,GIAO_DICH!$B$4:$B$13581,"<"&A17+1,GIAO_DICH!$C$4:$C$13581,"Kiểm hàng") -> 0 | F17: =B17+C17-D17+E17 -> 88 | H17: =IF(G17="","",G17-F17) | I17: =IF(H17="","",H17-H16) | J17: =IF(G17="","CHƯA KIỂM",IF(H17=0,"KHỚP",IF(H17>0,"DƯ","THIẾU"))) -> CHƯA KIỂM
A18: 46307 | B18: =F17 -> 88 | C18: =SUMIFS(GIAO_DICH!$F$4:$F$13581,GIAO_DICH!$B$4:$B$13581,">="&A18,GIAO_DICH!$B$4:$B$13581,"<"&A18+1,GIAO_DICH!$F$4:$F$13581,">0",GIAO_DICH!$C$4:$C$13581,"<>Kiểm hàng") -> 0 | D18: =-SUMIFS(GIAO_DICH!$F$4:$F$13581,GIAO_DICH!$B$4:$B$13581,">="&A18,GIAO_DICH!$B$4:$B$13581,"<"&A18+1,GIAO_DICH!$F$4:$F$13581,"<0",GIAO_DICH!$C$4:$C$13581,"<>Kiểm hàng") -> 0 | E18: =SUMIFS(GIAO_DICH!$F$4:$F$13581,GIAO_DICH!$B$4:$B$13581,">="&A18,GIAO_DICH!$B$4:$B$13581,"<"&A18+1,GIAO_DICH!$C$4:$C$13581,"Kiểm hàng") -> 0 | F18: =B18+C18-D18+E18 -> 88 | H18: =IF(G18="","",G18-F18) | I18: =IF(H18="","",H18-H17) | J18: =IF(G18="","CHƯA KIỂM",IF(H18=0,"KHỚP",IF(H18>0,"DƯ","THIẾU"))) -> CHƯA KIỂM
A19: 46308 | B19: =F18 -> 88 | C19: =SUMIFS(GIAO_DICH!$F$4:$F$13581,GIAO_DICH!$B$4:$B$13581,">="&A19,GIAO_DICH!$B$4:$B$13581,"<"&A19+1,GIAO_DICH!$F$4:$F$13581,">0",GIAO_DICH!$C$4:$C$13581,"<>Kiểm hàng") -> 0 | D19: =-SUMIFS(GIAO_DICH!$F$4:$F$13581,GIAO_DICH!$B$4:$B$13581,">="&A19,GIAO_DICH!$B$4:$B$13581,"<"&A19+1,GIAO_DICH!$F$4:$F$13581,"<0",GIAO_DICH!$C$4:$C$13581,"<>Kiểm hàng") -> 0 | E19: =SUMIFS(GIAO_DICH!$F$4:$F$13581,GIAO_DICH!$B$4:$B$13581,">="&A19,GIAO_DICH!$B$4:$B$13581,"<"&A19+1,GIAO_DICH!$C$4:$C$13581,"Kiểm hàng") -> 0 | F19: =B19+C19-D19+E19 -> 88 | H19: =IF(G19="","",G19-F19) | I19: =IF(H19="","",H19-H18) | J19: =IF(G19="","CHƯA KIỂM",IF(H19=0,"KHỚP",IF(H19>0,"DƯ","THIẾU"))) -> CHƯA KIỂM
A20: 46309 | B20: =F19 -> 88 | C20: =SUMIFS(GIAO_DICH!$F$4:$F$13581,GIAO_DICH!$B$4:$B$13581,">="&A20,GIAO_DICH!$B$4:$B$13581,"<"&A20+1,GIAO_DICH!$F$4:$F$13581,">0",GIAO_DICH!$C$4:$C$13581,"<>Kiểm hàng") -> 0 | D20: =-SUMIFS(GIAO_DICH!$F$4:$F$13581,GIAO_DICH!$B$4:$B$13581,">="&A20,GIAO_DICH!$B$4:$B$13581,"<"&A20+1,GIAO_DICH!$F$4:$F$13581,"<0",GIAO_DICH!$C$4:$C$13581,"<>Kiểm hàng") -> 0 | E20: =SUMIFS(GIAO_DICH!$F$4:$F$13581,GIAO_DICH!$B$4:$B$13581,">="&A20,GIAO_DICH!$B$4:$B$13581,"<"&A20+1,GIAO_DICH!$C$4:$C$13581,"Kiểm hàng") -> 0 | F20: =B20+C20-D20+E20 -> 88 | H20: =IF(G20="","",G20-F20) | I20: =IF(H20="","",H20-H19) | J20: =IF(G20="","CHƯA KIỂM",IF(H20=0,"KHỚP",IF(H20>0,"DƯ","THIẾU"))) -> CHƯA KIỂM
A21: 46310 | B21: =F20 -> 88 | C21: =SUMIFS(GIAO_DICH!$F$4:$F$13581,GIAO_DICH!$B$4:$B$13581,">="&A21,GIAO_DICH!$B$4:$B$13581,"<"&A21+1,GIAO_DICH!$F$4:$F$13581,">0",GIAO_DICH!$C$4:$C$13581,"<>Kiểm hàng") -> 0 | D21: =-SUMIFS(GIAO_DICH!$F$4:$F$13581,GIAO_DICH!$B$4:$B$13581,">="&A21,GIAO_DICH!$B$4:$B$13581,"<"&A21+1,GIAO_DICH!$F$4:$F$13581,"<0",GIAO_DICH!$C$4:$C$13581,"<>Kiểm hàng") -> 0 | E21: =SUMIFS(GIAO_DICH!$F$4:$F$13581,GIAO_DICH!$B$4:$B$13581,">="&A21,GIAO_DICH!$B$4:$B$13581,"<"&A21+1,GIAO_DICH!$C$4:$C$13581,"Kiểm hàng") -> 0 | F21: =B21+C21-D21+E21 -> 88 | H21: =IF(G21="","",G21-F21) | I21: =IF(H21="","",H21-H20) | J21: =IF(G21="","CHƯA KIỂM",IF(H21=0,"KHỚP",IF(H21>0,"DƯ","THIẾU"))) -> CHƯA KIỂM
A22: 46311 | B22: =F21 -> 88 | C22: =SUMIFS(GIAO_DICH!$F$4:$F$13581,GIAO_DICH!$B$4:$B$13581,">="&A22,GIAO_DICH!$B$4:$B$13581,"<"&A22+1,GIAO_DICH!$F$4:$F$13581,">0",GIAO_DICH!$C$4:$C$13581,"<>Kiểm hàng") -> 0 | D22: =-SUMIFS(GIAO_DICH!$F$4:$F$13581,GIAO_DICH!$B$4:$B$13581,">="&A22,GIAO_DICH!$B$4:$B$13581,"<"&A22+1,GIAO_DICH!$F$4:$F$13581,"<0",GIAO_DICH!$C$4:$C$13581,"<>Kiểm hàng") -> 0 | E22: =SUMIFS(GIAO_DICH!$F$4:$F$13581,GIAO_DICH!$B$4:$B$13581,">="&A22,GIAO_DICH!$B$4:$B$13581,"<"&A22+1,GIAO_DICH!$C$4:$C$13581,"Kiểm hàng") -> 0 | F22: =B22+C22-D22+E22 -> 88 | H22: =IF(G22="","",G22-F22) | I22: =IF(H22="","",H22-H21) | J22: =IF(G22="","CHƯA KIỂM",IF(H22=0,"KHỚP",IF(H22>0,"DƯ","THIẾU"))) -> CHƯA KIỂM
... A96: 46385 | B96: =F95 -> 88 | C96: =SUMIFS(GIAO_DICH!$F$4:$F$13581,GIAO_DICH!$B$4:$B$13581,">="&A96,GIAO_DICH!$B$4:$B$13581,"<"&A96+1,GIAO_DICH!$F$4:$F$13581,">0",GIAO_DICH!$C$4:$C$13581,"<>Kiểm hàng") -> 0 | D96: =-SUMIFS(GIAO_DICH!$F$4:$F$13581,GIAO_DICH!$B$4:$B$13581,">="&A96,GIAO_DICH!$B$4:$B$13581,"<"&A96+1,GIAO_DICH!$F$4:$F$13581,"<0",GIAO_DICH!$C$4:$C$13581,"<>Kiểm hàng") -> 0 | E96: =SUMIFS(GIAO_DICH!$F$4:$F$13581,GIAO_DICH!$B$4:$B$13581,">="&A96,GIAO_DICH!$B$4:$B$13581,"<"&A96+1,GIAO_DICH!$C$4:$C$13581,"Kiểm hàng") -> 0 | F96: =B96+C96-D96+E96 -> 88 | H96: =IF(G96="","",G96-F96) | I96: =IF(H96="","",H96-H95) | J96: =IF(G96="","CHƯA KIỂM",IF(H96=0,"KHỚP",IF(H96>0,"DƯ","THIẾU"))) -> CHƯA KIỂM

Sheet GIAO_DICH
A1: GIAO_DICH — FORM GIỮ NGUYÊN THEO FILE KIOT
A2: Để cập nhật: copy dữ liệu từ file Kiot (không lấy hàng tiêu đề) và paste vào ô A4. Không đổi thứ tự 9 cột; không cần tách Nhập/Xuất.
A3: Chứng từ | B3: Thời gian | C3: Loại giao dịch | D3: Giá giao dịch | E3: Giá vốn | F3: Số lượng | G3: Tồn cuối | H3: Đối tác
A4: HD048201 | B4: 46299.381 | C4: Bán hàng | D4: 200000 | E4: 0 | F4: -2 | G4: 88 | H4: YAGAMI ĐẠI HỌC
A5: PN002474 | B5: 46298.648 | C5: Nhập hàng | D5: 0 | E5: 0 | F5: 200 | G5: 90
A6: TRF000210 | B6: 46298.587 | C6: Chuyển hàng | E6: 0 | F6: -70 | G6: -110
A7: HD048176.01 | B7: 46298.58 | C7: Bán hàng | D7: 205000 | E7: 0 | F7: -5 | G7: -40 | H7: YAGAMI BẠC LIÊU
A8: HD048169 | B8: 46298.416 | C8: Bán hàng | D8: 200000 | E8: 0 | F8: -2 | G8: -35 | H8: YAGAMI ĐẠI HỌC
A9: HD048166 | B9: 46298.409 | C9: Bán hàng | D9: 205000 | E9: 0 | F9: -40 | G9: -33 | H9: YAGAMI PHÚ TÂN
A10: HD048165 | B10: 46298.312 | C10: Bán hàng | D10: 205000 | E10: 0 | F10: -5 | G10: 7 | H10: YAGAMI CÁI TÀU HẠ
A11: HD048144 | B11: 46297.586 | C11: Bán hàng | D11: 205000 | E11: 0 | F11: -10 | G11: 12 | H11: YAGAMI TÂN THẠNH
A12: HD048130 | B12: 46297.465 | C12: Bán hàng | D12: 205000 | E12: 0 | F12: -20 | G12: 22 | H12: YAGAMI THÁP MƯỜI
A13: HD048122 | B13: 46297.453 | C13: Bán hàng | D13: 205000 | E13: 0 | F13: -5 | G13: 42 | H13: YAGAMI NĂM CĂN
A14: HD048121 | B14: 46297.444 | C14: Bán hàng | D14: 200000 | E14: 0 | F14: -3 | G14: 47 | H14: YAGAMI ĐẠI HỌC
A15: KK000770 | B15: 46296.668 | C15: Kiểm hàng | E15: 0 | F15: -5 | G15: 50
A16: HD048087.02 | B16: 46296.584 | C16: Bán hàng | D16: 205000 | E16: 0 | F16: -1 | G16: 55 | H16: YAGAMI MỘT NGÀN
A17: HD048080 | B17: 46296.579 | C17: Bán hàng | D17: 205000 | E17: 0 | F17: -30 | G17: 56 | H17: YAGAMI THỐT NỐT
A18: HD048076 | B18: 46296.573 | C18: Bán hàng | D18: 200000 | E18: 0 | F18: -3 | G18: 86 | H18: YAGAMI ĐẠI HỌC
A19: HD048049 | B19: 46295.465 | C19: Bán hàng | D19: 205000 | E19: 0 | F19: -10 | G19: 89 | H19: YAGAMI AN PHÚ
A20: HD048041 | B20: 46295.458 | C20: Bán hàng | D20: 205000 | E20: 0 | F20: -15 | G20: 99 | H20: YAGAMI CHÂU PHÚ
A21: HD048038 | B21: 46295.455 | C21: Bán hàng | D21: 200000 | E21: 0 | F21: -2 | G21: 114 | H21: YAGAMI ĐẠI HỌC
A22: HD048027 | B22: 46295.387 | C22: Bán hàng | D22: 205000 | E22: 0 | F22: -2 | G22: 116 | H22: YAGAMI RẠCH SỎI
A23: HD047990 | B23: 46294.573 | C23: Bán hàng | D23: 205000 | E23: 0 | F23: -3 | G23: 118 | H23: YAGAMI CÁI TÀU HẠ
A24: HD047989 | B24: 46294.573 | C24: Bán hàng | D24: 200000 | E24: 0 | F24: -3 | G24: 121 | H24: YAGAMI ĐẠI HỌC
A25: HD047915 | B25: 46293.439 | C25: Bán hàng | D25: 200000 | E25: 0 | F25: -2 | G25: 124 | H25: YAGAMI ĐẠI HỌC
A26: TRF000205 | B26: 46292.633 | C26: Chuyển hàng | E26: 0 | F26: -40 | G26: 126
A27: PN002451 | B27: 46292.624 | C27: Nhập hàng | D27: 0 | E27: 0 | F27: 70 | G27: 166
A28: TRF000204 | B28: 46292.41 | C28: Chuyển hàng | E28: 0 | F28: -30 | G28: 96
A29: HD047899 | B29: 46292.41 | C29: Bán hàng | D29: 200000 | E29: 0 | F29: -3 | G29: 126 | H29: YAGAMI ĐẠI HỌC
A30: HD047883 | B30: 46291.586 | C30: Bán hàng | D30: 205000 | E30: 0 | F30: -5 | G30: 129 | H30: YAGAMI MỸ LUÔNG
A31: HD047864 | B31: 46291.45 | C31: Bán hàng | D31: 200000 | E31: 0 | F31: -3 | G31: 134 | H31: YAGAMI ĐẠI HỌC
A32: HD047836 | B32: 46290.579 | C32: Bán hàng | D32: 205000 | E32: 0 | F32: -5 | G32: 137 | H32: YAGAMI THÁP MƯỜI
A33: HD047828 | B33: 46290.571 | C33: Bán hàng | D33: 200000 | E33: 0 | F33: -3 | G33: 142 | H33: YAGAMI ĐẠI HỌC
A34: HD047811 | B34: 46289.6 | C34: Bán hàng | D34: 205000 | E34: 0 | F34: -30 | G34: 145 | H34: YAGAMI THỐT NỐT
A35: HD047794 | B35: 46289.587 | C35: Bán hàng | D35: 205000 | E35: 0 | F35: -4 | G35: 175 | H35: YAGAMI LẤP VÒ
A36: HD047787 | B36: 46289.581 | C36: Bán hàng | D36: 200000 | E36: 0 | F36: -3 | G36: 179 | H36: YAGAMI ĐẠI HỌC
A37: HD047778 | B37: 46289.407 | C37: Bán hàng | D37: 205000 | E37: 0 | F37: -1 | G37: 182 | H37: YAGAMI MỘT NGÀN
A38: HD047776.01 | B38: 46289.388 | C38: Bán hàng | D38: 205000 | E38: 0 | F38: -4 | G38: 183 | H38: YAGAMI TRUNG AN
A39: HD047763 | B39: 46288.601 | C39: Bán hàng | D39: 205000 | E39: 0 | F39: -1 | G39: 187 | H39: YAGAMI QUỐC THÁI
A40: HD047748 | B40: 46288.59 | C40: Bán hàng | D40: 205000 | E40: 0 | F40: -20 | G40: 188 | H40: YAGAMI CÁI TÀU HẠ
...

Sheet HUONG_DAN
A1: CÁCH PASTE FILE KIOT
A2: 1. Mở file Kiot, bỏ dòng tiêu đề và copy 9 cột dữ liệu: Chứng từ đến Tồn thực tế.
A3: 2. Mở sheet GIAO_DICH, chọn ô A4 và paste. Tuyệt đối không chèn/xóa/đổi thứ tự cột.
A4: 3. Bảng tổng hợp nhận ngày từ cột Thời gian (bao gồm cả giờ), nên không bị lỗi do điều kiện ngày có giờ.
A5: 4. Nhập sổ = số lượng dương trừ Kiểm hàng; Xuất sổ = trị tuyệt đối số lượng âm trừ Kiểm hàng; Kiểm hàng vào Điều chỉnh.
